Workbook

Sheet Slide Calc
A1: P&L By Channel — slide calculator
A2: Pick Period and Channel (yellow). Every figure on the slide is calculated below with SUMIFS on the Data sheet.
A4: Period | B4: YTD Aug 26
A5: Channel | B5: OOH
A7: 1. P&L lines
A8: Line | B8: ACT | C8: RE | D8: BP | E8: PY | F8: Type
A9: Volume | B9: =SUMIFS(Data!$E$5:$E$172,Data!$A$5:$A$172,$B$4,Data!$B$5:$B$172,$B$5,Data!$C$5:$C$172,$A9,Data!$D$5:$D$172,B$8) -> 62.155 | C9: =SUMIFS(Data!$E$5:$E$172,Data!$A$5:$A$172,$B$4,Data!$B$5:$B$172,$B$5,Data!$C$5:$C$172,$A9,Data!$D$5:$D$172,C$8) -> 62.195 | D9: =SUMIFS(Data!$E$5:$E$172,Data!$A$5:$A$172,$B$4,Data!$B$5:$B$172,$B$5,Data!$C$5:$C$172,$A9,Data!$D$5:$D$172,D$8) -> 61.519 | E9: =SUMIFS(Data!$E$5:$E$172,Data!$A$5:$A$172,$B$4,Data!$B$5:$B$172,$B$5,Data!$C$5:$C$172,$A9,Data!$D$5:$D$172,E$8) -> 57.624 | F9: rev
A10: GSR | B10: =SUMIFS(Data!$E$5:$E$172,Data!$A$5:$A$172,$B$4,Data!$B$5:$B$172,$B$5,Data!$C$5:$C$172,$A10,Data!$D$5:$D$172,B$8) -> 507.138 | C10: =SUMIFS(Data!$E$5:$E$172,Data!$A$5:$A$172,$B$4,Data!$B$5:$B$172,$B$5,Data!$C$5:$C$172,$A10,Data!$D$5:$D$172,C$8) -> 508.119 | D10: =SUMIFS(Data!$E$5:$E$172,Data!$A$5:$A$172,$B$4,Data!$B$5:$B$172,$B$5,Data!$C$5:$C$172,$A10,Data!$D$5:$D$172,D$8) -> 502.777 | E10: =SUMIFS(Data!$E$5:$E$172,Data!$A$5:$A$172,$B$4,Data!$B$5:$B$172,$B$5,Data!$C$5:$C$172,$A10,Data!$D$5:$D$172,E$8) -> 465.569 | F10: rev
A11: Discounts | B11: =SUMIFS(Data!$E$5:$E$172,Data!$A$5:$A$172,$B$4,Data!$B$5:$B$172,$B$5,Data!$C$5:$C$172,$A11,Data!$D$5:$D$172,B$8) -> 173.694 | C11: =SUMIFS(Data!$E$5:$E$172,Data!$A$5:$A$172,$B$4,Data!$B$5:$B$172,$B$5,Data!$C$5:$C$172,$A11,Data!$D$5:$D$172,C$8) -> 174.093 | D11: =SUMIFS(Data!$E$5:$E$172,Data!$A$5:$A$172,$B$4,Data!$B$5:$B$172,$B$5,Data!$C$5:$C$172,$A11,Data!$D$5:$D$172,D$8) -> 165.849 | E11: =SUMIFS(Data!$E$5:$E$172,Data!$A$5:$A$172,$B$4,Data!$B$5:$B$172,$B$5,Data!$C$5:$C$172,$A11,Data!$D$5:$D$172,E$8) -> 149.266 | F11: cost
A12: NSR | B12: =SUMIFS(Data!$E$5:$E$172,Data!$A$5:$A$172,$B$4,Data!$B$5:$B$172,$B$5,Data!$C$5:$C$172,$A12,Data!$D$5:$D$172,B$8) -> 333.444 | C12: =SUMIFS(Data!$E$5:$E$172,Data!$A$5:$A$172,$B$4,Data!$B$5:$B$172,$B$5,Data!$C$5:$C$172,$A12,Data!$D$5:$D$172,C$8) -> 334.026 | D12: =SUMIFS(Data!$E$5:$E$172,Data!$A$5:$A$172,$B$4,Data!$B$5:$B$172,$B$5,Data!$C$5:$C$172,$A12,Data!$D$5:$D$172,D$8) -> 336.928 | E12: =SUMIFS(Data!$E$5:$E$172,Data!$A$5:$A$172,$B$4,Data!$B$5:$B$172,$B$5,Data!$C$5:$C$172,$A12,Data!$D$5:$D$172,E$8) -> 316.303 | F12: rev
A13: COGS | B13: =SUMIFS(Data!$E$5:$E$172,Data!$A$5:$A$172,$B$4,Data!$B$5:$B$172,$B$5,Data!$C$5:$C$172,$A13,Data!$D$5:$D$172,B$8) -> 216.392 | C13: =SUMIFS(Data!$E$5:$E$172,Data!$A$5:$A$172,$B$4,Data!$B$5:$B$172,$B$5,Data!$C$5:$C$172,$A13,Data!$D$5:$D$172,C$8) -> 217.443 | D13: =SUMIFS(Data!$E$5:$E$172,Data!$A$5:$A$172,$B$4,Data!$B$5:$B$172,$B$5,Data!$C$5:$C$172,$A13,Data!$D$5:$D$172,D$8) -> 215.185 | E13: =SUMIFS(Data!$E$5:$E$172,Data!$A$5:$A$172,$B$4,Data!$B$5:$B$172,$B$5,Data!$C$5:$C$172,$A13,Data!$D$5:$D$172,E$8) -> 202.343 | F13: cost
A14: GP | B14: =SUMIFS(Data!$E$5:$E$172,Data!$A$5:$A$172,$B$4,Data!$B$5:$B$172,$B$5,Data!$C$5:$C$172,$A14,Data!$D$5:$D$172,B$8) -> 117.051 | C14: =SUMIFS(Data!$E$5:$E$172,Data!$A$5:$A$172,$B$4,Data!$B$5:$B$172,$B$5,Data!$C$5:$C$172,$A14,Data!$D$5:$D$172,C$8) -> 116.583 | D14: =SUMIFS(Data!$E$5:$E$172,Data!$A$5:$A$172,$B$4,Data!$B$5:$B$172,$B$5,Data!$C$5:$C$172,$A14,Data!$D$5:$D$172,D$8) -> 121.743 | E14: =SUMIFS(Data!$E$5:$E$172,Data!$A$5:$A$172,$B$4,Data!$B$5:$B$172,$B$5,Data!$C$5:$C$172,$A14,Data!$D$5:$D$172,E$8) -> 113.96 | F14: rev
A15: DME | B15: =SUMIFS(Data!$E$5:$E$172,Data!$A$5:$A$172,$B$4,Data!$B$5:$B$172,$B$5,Data!$C$5:$C$172,$A15,Data!$D$5:$D$172,B$8) -> 6.867 | C15: =SUMIFS(Data!$E$5:$E$172,Data!$A$5:$A$172,$B$4,Data!$B$5:$B$172,$B$5,Data!$C$5:$C$172,$A15,Data!$D$5:$D$172,C$8) -> 7.095 | D15: =SUMIFS(Data!$E$5:$E$172,Data!$A$5:$A$172,$B$4,Data!$B$5:$B$172,$B$5,Data!$C$5:$C$172,$A15,Data!$D$5:$D$172,D$8) -> 7.451 | E15: =SUMIFS(Data!$E$5:$E$172,Data!$A$5:$A$172,$B$4,Data!$B$5:$B$172,$B$5,Data!$C$5:$C$172,$A15,Data!$D$5:$D$172,E$8) -> 5.154 | F15: cost
A16: Sales Opex | B16: =SUMIFS(Data!$E$5:$E$172,Data!$A$5:$A$172,$B$4,Data!$B$5:$B$172,$B$5,Data!$C$5:$C$172,$A16,Data!$D$5:$D$172,B$8) -> 60.886 | C16: =SUMIFS(Data!$E$5:$E$172,Data!$A$5:$A$172,$B$4,Data!$B$5:$B$172,$B$5,Data!$C$5:$C$172,$A16,Data!$D$5:$D$172,C$8) -> 61.088 | D16: =SUMIFS(Data!$E$5:$E$172,Data!$A$5:$A$172,$B$4,Data!$B$5:$B$172,$B$5,Data!$C$5:$C$172,$A16,Data!$D$5:$D$172,D$8) -> 62.683 | E16: =SUMIFS(Data!$E$5:$E$172,Data!$A$5:$A$172,$B$4,Data!$B$5:$B$172,$B$5,Data!$C$5:$C$172,$A16,Data!$D$5:$D$172,E$8) -> 57.797 | F16: cost
A17: Mktg Opex | B17: =SUMIFS(Data!$E$5:$E$172,Data!$A$5:$A$172,$B$4,Data!$B$5:$B$172,$B$5,Data!$C$5:$C$172,$A17,Data!$D$5:$D$172,B$8) -> 3.706 | C17: =SUMIFS(Data!$E$5:$E$172,Data!$A$5:$A$172,$B$4,Data!$B$5:$B$172,$B$5,Data!$C$5:$C$172,$A17,Data!$D$5:$D$172,C$8) -> 3.634 | D17: =SUMIFS(Data!$E$5:$E$172,Data!$A$5:$A$172,$B$4,Data!$B$5:$B$172,$B$5,Data!$C$5:$C$172,$A17,Data!$D$5:$D$172,D$8) -> 3.248 | E17: =SUMIFS(Data!$E$5:$E$172,Data!$A$5:$A$172,$B$4,Data!$B$5:$B$172,$B$5,Data!$C$5:$C$172,$A17,Data!$D$5:$D$172,E$8) -> 3.452 | F17: cost
A18: Distribution and Delivery | B18: =SUMIFS(Data!$E$5:$E$172,Data!$A$5:$A$172,$B$4,Data!$B$5:$B$172,$B$5,Data!$C$5:$C$172,$A18,Data!$D$5:$D$172,B$8) -> 19.156 | C18: =SUMIFS(Data!$E$5:$E$172,Data!$A$5:$A$172,$B$4,Data!$B$5:$B$172,$B$5,Data!$C$5:$C$172,$A18,Data!$D$5:$D$172,C$8) -> 19.346 | D18: =SUMIFS(Data!$E$5:$E$172,Data!$A$5:$A$172,$B$4,Data!$B$5:$B$172,$B$5,Data!$C$5:$C$172,$A18,Data!$D$5:$D$172,D$8) -> 16.666 | E18: =SUMIFS(Data!$E$5:$E$172,Data!$A$5:$A$172,$B$4,Data!$B$5:$B$172,$B$5,Data!$C$5:$C$172,$A18,Data!$D$5:$D$172,E$8) -> 16.618 | F18: cost
A19: Warehouse | B19: =SUMIFS(Data!$E$5:$E$172,Data!$A$5:$A$172,$B$4,Data!$B$5:$B$172,$B$5,Data!$C$5:$C$172,$A19,Data!$D$5:$D$172,B$8) -> 13.12 | C19: =SUMIFS(Data!$E$5:$E$172,Data!$A$5:$A$172,$B$4,Data!$B$5:$B$172,$B$5,Data!$C$5:$C$172,$A19,Data!$D$5:$D$172,C$8) -> 13.097 | D19: =SUMIFS(Data!$E$5:$E$172,Data!$A$5:$A$172,$B$4,Data!$B$5:$B$172,$B$5,Data!$C$5:$C$172,$A19,Data!$D$5:$D$172,D$8) -> 12.245 | E19: =SUMIFS(Data!$E$5:$E$172,Data!$A$5:$A$172,$B$4,Data!$B$5:$B$172,$B$5,Data!$C$5:$C$172,$A19,Data!$D$5:$D$172,E$8) -> 11.848 | F19: cost
A20: Administration | B20: =SUMIFS(Data!$E$5:$E$172,Data!$A$5:$A$172,$B$4,Data!$B$5:$B$172,$B$5,Data!$C$5:$C$172,$A20,Data!$D$5:$D$172,B$8) -> 10.676 | C20: =SUMIFS(Data!$E$5:$E$172,Data!$A$5:$A$172,$B$4,Data!$B$5:$B$172,$B$5,Data!$C$5:$C$172,$A20,Data!$D$5:$D$172,C$8) -> 10.189 | D20: =SUMIFS(Data!$E$5:$E$172,Data!$A$5:$A$172,$B$4,Data!$B$5:$B$172,$B$5,Data!$C$5:$C$172,$A20,Data!$D$5:$D$172,D$8) -> 11.409 | E20: =SUMIFS(Data!$E$5:$E$172,Data!$A$5:$A$172,$B$4,Data!$B$5:$B$172,$B$5,Data!$C$5:$C$172,$A20,Data!$D$5:$D$172,E$8) -> 9.703 | F20: cost
... A22: Underlying EBIT | B22: =SUMIFS(Data!$E$5:$E$172,Data!$A$5:$A$172,$B$4,Data!$B$5:$B$172,$B$5,Data!$C$5:$C$172,$A22,Data!$D$5:$D$172,B$8) -> 2.641 | C22: =SUMIFS(Data!$E$5:$E$172,Data!$A$5:$A$172,$B$4,Data!$B$5:$B$172,$B$5,Data!$C$5:$C$172,$A22,Data!$D$5:$D$172,C$8) -> 2.135 | D22: =SUMIFS(Data!$E$5:$E$172,Data!$A$5:$A$172,$B$4,Data!$B$5:$B$172,$B$5,Data!$C$5:$C$172,$A22,Data!$D$5:$D$172,D$8) -> 8.042 | E22: =SUMIFS(Data!$E$5:$E$172,Data!$A$5:$A$172,$B$4,Data!$B$5:$B$172,$B$5,Data!$C$5:$C$172,$A22,Data!$D$5:$D$172,E$8) -> 9.361 | F22: rev
A23: W&D | B23: =B18+B19 -> 32.276 | C23: =C18+C19 -> 32.443 | D23: =D18+D19 -> 28.911 | E23: =E18+E19 -> 28.466 | F23: cost
A24: Net Contribution | B24: =B14-B23 -> 84.775 | C24: =C14-C23 -> 84.14 | D24: =D14-D23 -> 92.832 | E24: =E14-E23 -> 85.494 | F24: rev
A25: Opex excl. W&D | B25: =B21-B23 -> 75.267 | C25: =C21-C23 -> 74.911 | D25: =D21-D23 -> 77.34 | E25: =E21-E23 -> 70.979 | F25: cost
A26: Other / SoI (plug) | B26: =B22-(B24-B25-B15) -> 0 | C26: =C22-(C24-C25-C15) -> 0.001 | D26: =D22-(D24-D25-D15) -> 0.001 | E26: =E22-(E24-E25-E15) -> 0 | F26: rev
A28: Margins on NSR
A29: GP % | B29: =IFERROR(B14/B12,0) -> 0.35103646 | C29: =IFERROR(C14/C12,0) -> 0.34902373 | D29: =IFERROR(D14/D12,0) -> 0.36133239 | E29: =IFERROR(E14/E12,0) -> 0.36028745
A30: NC % | B30: =IFERROR(B24/B12,0) -> 0.25424059 | C30: =IFERROR(C24/C12,0) -> 0.25189656 | D30: =IFERROR(D24/D12,0) -> 0.27552474 | E30: =IFERROR(E24/E12,0) -> 0.27029146
A31: EBIT % | B31: =IFERROR(B22/B12,0) -> 0.0079203704 | C31: =IFERROR(C22/C12,0) -> 0.006391718 | D31: =IFERROR(D22/D12,0) -> 0.023868601 | E31: =IFERROR(E22/E12,0) -> 0.02959504
A32: Discount rate (on GSR) | B32: =IFERROR(B11/B10,0) -> 0.34249849 | C32: =IFERROR(C11/C10,0) -> 0.3426225 | D32: =IFERROR(D11/D10,0) -> 0.32986592 | E32: =IFERROR(E11/E10,0) -> 0.32060983
A34: 2. Variances (+ = favourable to EBIT)
A35: Line | B35: vs RE | C35: vs BP | D35: vs PY
A36: Volume | B36: =IF($F9="cost",C9-$B9,$B9-C9) -> -0.04 | C36: =IF($F9="cost",D9-$B9,$B9-D9) -> 0.636 | D36: =IF($F9="cost",E9-$B9,$B9-E9) -> 4.531
A37: NSR | B37: =IF($F12="cost",C12-$B12,$B12-C12) -> -0.582 | C37: =IF($F12="cost",D12-$B12,$B12-D12) -> -3.484 | D37: =IF($F12="cost",E12-$B12,$B12-E12) -> 17.141
A38: COGS | B38: =IF($F13="cost",C13-$B13,$B13-C13) -> 1.051 | C38: =IF($F13="cost",D13-$B13,$B13-D13) -> -1.207 | D38: =IF($F13="cost",E13-$B13,$B13-E13) -> -14.049
A39: GP | B39: =IF($F14="cost",C14-$B14,$B14-C14) -> 0.468 | C39: =IF($F14="cost",D14-$B14,$B14-D14) -> -4.692 | D39: =IF($F14="cost",E14-$B14,$B14-E14) -> 3.091
A40: W&D | B40: =IF($F23="cost",C23-$B23,$B23-C23) -> 0.167 | C40: =IF($F23="cost",D23-$B23,$B23-D23) -> -3.365 | D40: =IF($F23="cost",E23-$B23,$B23-E23) -> -3.81
A41: Net Contribution | B41: =IF($F24="cost",C24-$B24,$B24-C24) -> 0.635 | C41: =IF($F24="cost",D24-$B24,$B24-D24) -> -8.057 | D41: =IF($F24="cost",E24-$B24,$B24-E24) -> -0.719
A42: Opex excl. W&D | B42: =IF($F25="cost",C25-$B25,$B25-C25) -> -0.356 | C42: =IF($F25="cost",D25-$B25,$B25-D25) -> 2.073 | D42: =IF($F25="cost",E25-$B25,$B25-E25) -> -4.288
A43: DME | B43: =IF($F15="cost",C15-$B15,$B15-C15) -> 0.228 | C43: =IF($F15="cost",D15-$B15,$B15-D15) -> 0.584 | D43: =IF($F15="cost",E15-$B15,$B15-E15) -> -1.713
A44: Other / SoI (plug) | B44: =IF($F26="cost",C26-$B26,$B26-C26) -> -0.001 | C44: =IF($F26="cost",D26-$B26,$B26-D26) -> -0.001 | D44: =IF($F26="cost",E26-$B26,$B26-E26) -> 0
A45: Underlying EBIT | B45: =IF($F22="cost",C22-$B22,$B22-C22) -> 0.506 | C45: =IF($F22="cost",D22-$B22,$B22-D22) -> -5.401 | D45: =IF($F22="cost",E22-$B22,$B22-E22) -> -6.72
...

Sheet Data
A1: P&L By Channel — source data (long format)
A2: One row per Period × Channel × Line × Scenario. Paste new periods below; Slide Calc picks them up via SUMIFS. Units: volume m UC, values mio€.
A4: Period | B4: Channel | C4: Line | D4: Scenario | E4: Value
A5: YTD Aug 26 | B5: Total | C5: Volume | D5: ACT | E5: 177.755
A6: YTD Aug 26 | B6: Total | C6: Volume | D6: RE | E6: 176.484
A7: YTD Aug 26 | B7: Total | C7: Volume | D7: BP | E7: 175.188
A8: YTD Aug 26 | B8: Total | C8: Volume | D8: PY | E8: 170.621
A9: YTD Aug 26 | B9: Total | C9: GSR | D9: ACT | E9: 1684.732
A10: YTD Aug 26 | B10: Total | C10: GSR | D10: RE | E10: 1674.236
A11: YTD Aug 26 | B11: Total | C11: GSR | D11: BP | E11: 1657.958
A12: YTD Aug 26 | B12: Total | C12: GSR | D12: PY | E12: 1534.797
A13: YTD Aug 26 | B13: Total | C13: Discounts | D13: ACT | E13: 760.631
A14: YTD Aug 26 | B14: Total | C14: Discounts | D14: RE | E14: 756.828
A15: YTD Aug 26 | B15: Total | C15: Discounts | D15: BP | E15: 744.031
A16: YTD Aug 26 | B16: Total | C16: Discounts | D16: PY | E16: 664.508
... A172: YTD Aug 26 | B172: OOH | C172: Underlying EBIT | D172: PY | E172: 9.361

Sheet EBIT Bridge vs RE
A1: YTD August 2026 — EBIT Bridge vs RE 6+6 (mio€)
A2: Source: YTD vs RE driver bridge (FP&A), August 2026. Inputs in blue are typed from the bridge; everything else is formula.
A4: Step | B4: EBIT effect | C4: Cumulative | D4: Base (hidden) | E4: Up | F4: Down | G4: Ends | H4: Comment
A5: EBIT YTD RE 6+6 | B5: 109.7 | C5: =B5 -> 109.7 | D5: 0 | E5: 0 | F5: 0 | G5: =B5 -> 109.7 | H5: Rolling estimate 6+6
A6: Volume Impact | B6: 2.75 | C6: =C5+B6 -> 112.45 | D6: =MIN(C5,C6) -> 109.7 | E6: =IF(B6>0,B6,0) -> 2.75 | F6: =IF(B6<0,-B6,0) -> 0 | G6: 0 | H6: Volumes +1.3m UC vs RE (+0.7%): MT +1.4m UC and Sparkling Bev Core +1.6m UC; WHS -0.6m UC, Water Regular and Sport Drinks below estimate
A7: Category Mix | B7: 1.27 | C7: =C6+B7 -> 113.72 | D7: =MIN(C6,C7) -> 112.45 | E7: =IF(B7>0,B7,0) -> 1.27 | F7: =IF(B7<0,-B7,0) -> 0 | G7: 0 | H7: Category mix positive: lower Water Regular (-0.2m UC), higher Sparkling Bev Core (+1.6m UC); brand mix positive on Coca-Cola Zero
A8: Pack mix | B8: -1.25 | C8: =C7+B8 -> 112.47 | D8: =MIN(C7,C8) -> 112.47 | E8: =IF(B8>0,B8,0) -> 0 | F8: =IF(B8<0,-B8,0) -> 1.25 | G8: 0 | H8: Higher PET MS and BIB, lower glass (NRG and RGB SSD); partially recovered by CAN 0.330L Sparkling Bev Core
A9: Channel Mix | B9: -0.43 | C9: =C8+B9 -> 112.04 | D9: =MIN(C8,C9) -> 112.04 | E9: =IF(B9>0,B9,0) -> 0 | F9: =IF(B9<0,-B9,0) -> 0.43 | G9: 0 | H9: AH +1.1% vs OOH -0.1% against RE
A10: NSR Pricing | B10: 1.34 | C10: =C9+B10 -> 113.38 | D10: =MIN(C9,C10) -> 112.04 | E10: =IF(B10>0,B10,0) -> 1.34 | F10: =IF(B10<0,-B10,0) -> 0 | G10: 0 | H10: Positive phasing in Listing Fees and Disposals (anticipated from Q4, +2.2m) offsets higher activations; AH volume sold at old prices -0.3m and incidence effect -0.5m
A11: Concentrate | B11: -0.18 | C11: =C10+B11 -> 113.2 | D11: =MIN(C10,C11) -> 113.2 | E11: =IF(B11>0,B11,0) -> 0 | F11: =IF(B11<0,-B11,0) -> 0.18 | G11: 0 | H11: Higher gross concentrate cost (logistics, yields/consumption), partially offset by McD PS benefit
A12: Raw Material | B12: 1.51 | C12: =C11+B12 -> 114.71 | D12: =MIN(C11,C12) -> 113.2 | E12: =IF(B12>0,B12,0) -> 1.51 | F12: =IF(B12<0,-B12,0) -> 0 | G12: 0 | H12: Lower secondary packaging cost (+1.3m: beginning inventories, scaling on purchased quantities, GR/IR) and Monster PS (+0.4m); higher sugar, aluminium and resin
A13: POH & Haulage | B13: 0.35 | C13: =C12+B13 -> 115.06 | D13: =MIN(C12,C13) -> 114.71 | E13: =IF(B13>0,B13,0) -> 0.35 | F13: =IF(B13<0,-B13,0) -> 0 | G13: 0 | H13: Lower people cost and lower losses (CG reimbursement for Marcianise, one-off) fully offset negative recoveries; haulage -150k on recovery phasing
A14: DME | B14: -0.42 | C14: =C13+B14 -> 114.64 | D14: =MIN(C13,C14) -> 114.64 | E14: =IF(B14>0,B14,0) -> 0 | F14: =IF(B14<0,-B14,0) -> 0.42 | G14: 0 | H14: Phasing in settlement with KO (TCCC contribution)
A15: OPEX excl. DME | B15: -0.57 | C15: =C14+B15 -> 114.07 | D15: =MIN(C14,C15) -> 114.07 | E15: =IF(B15>0,B15,0) -> 0 | F15: =IF(B15<0,-B15,0) -> 0.57 | G15: 0 | H15: Higher Admin OPEX (planned efficiencies funded in actuals by NSR), partially offset by logistics CTS ex haulage +0.2m (Distribution optimisation and lower fuel in August)
A16: SoI | B16: -0.01 | C16: =C15+B16 -> 114.06 | D16: =MIN(C15,C16) -> 114.06 | E16: =IF(B16>0,B16,0) -> 0 | F16: =IF(B16<0,-B16,0) -> 0.01 | G16: 0 | H16: In line with RE
A17: Other / One offs | B17: 1.19 | C17: =C16+B17 -> 115.25 | D17: =MIN(C16,C17) -> 114.06 | E17: =IF(B17>0,B17,0) -> 1.19 | F17: =IF(B17<0,-B17,0) -> 0 | G17: 0 | H17: Net effect of I/C +0.4m, Olympics balancing in DME +0.4m (part shifted from OPEX Admin), higher volume sold to other bottler FBO +0.3m
A18: EBIT YTD 2026 | B18: =SUM(B5:B17) -> 115.25 | C18: =B18 -> 115.25 | D18: 0 | E18: 0 | F18: 0 | G18: =B18 -> 115.25 | H18: Actual YTD August
A20: Check: ACT EBIT per bridge | B20: 115.25 | C20: Typed from bridge ACT row (115.25)
A21: Difference (should be ~0, rounding) | B21: =B18-B20 -> 0
A23: Legend
A24: Blue = input typed from the FP&A bridge (edit here). Black = formula. Columns D–G drive the waterfall chart (hidden base + up/down + end bars).
A25: NSR Pricing = Discounts (+2.16) + Net Pricing (-0.82), combined as on the vs PY bridge slide. Category Mix = Brand Mix row of the bridge.

Sheet Bridge rows (source)
A1: YTD vs RE 6+6 — rows as read from the FP&A bridge (mio€, EBIT variance column)
A3: Row | B3: EBIT effect
A4: Volume Impact | B4: 2.75
A5: Brand Mix (category + brand) | B5: 1.27
A6: Package Mix | B6: -1.25
A7: Channel Mix | B7: -0.43
A8: Discounts | B8: 2.16
A9: Net Pricing | B9: -0.82
A10: TCCC Conc. | B10: -0.18
A11: Input Cost (excl. Conc.) | B11: 1.51
A12: Prod OHs and Haul. | B12: 0.35
A13: DME | B13: -0.42
A14: OPEX excl. DME | B14: -0.57
A15: Share of IA | B15: -0.01
A16: Other / One offs | B16: 1.19
A17: Total | B17: =SUM(B4:B16) -> 5.55
A18: Bridge total as displayed: 5.53 (rounding)
